<rss xmlns:atom="http://www.w3.org/2005/Atom" version="2.0"><channel><title>Context - 태그 - 김영천 블로그</title><link>https://yeongcheon.github.io/tags/context/</link><description>Context - 태그 - 김영천 블로그</description><generator>Hugo -- gohugo.io</generator><language>ko</language><lastBuildDate>Fri, 05 Feb 2021 00:00:00 +0000</lastBuildDate><atom:link href="https://yeongcheon.github.io/tags/context/" rel="self" type="application/rss+xml"/><item><title>cloud function 호출 시 context의 중요성에 대해 알아보자.</title><link>https://yeongcheon.github.io/posts/2021-02-05-cloud-function-context-problem/</link><pubDate>Fri, 05 Feb 2021 00:00:00 +0000</pubDate><author>yeongcheon</author><guid>https://yeongcheon.github.io/posts/2021-02-05-cloud-function-context-problem/</guid><description><![CDATA[<p>
<a href="/posts/2021-01-06-image-resize-cloud-function.html">예전 글</a>에서 언급한 <a href="https://github.com/YeongCheon/imagick-cf">imagick-cf</a>를 테스트 하는 도중 마주한 알 수 없는 특이한 오류와 이를 해결했던 과정을 기록합니다.</p>
<div id="outline-container-headline-1" class="outline-2">
<h2 id="headline-1">
문제
</h2>
<div id="outline-text-headline-1" class="outline-text-2">
<ol>
<li>url을 통해서 함수를 실행하면 최초 실행 후 일정 시간동안은 몇번을 호출하든 결과가 정상적으로 반환합니다. </li>
<li>하지만 이후 500 에러를 반환하기 시작합니다. 심지어 이 전에 정상적으로 반환했던 url을 그대로 호출해도 500 error를 반환하는 어처구니 없는 모습을 보여줍니다. </li>
<li>게다가 500 에러를 반환하는 경우엔 로그조차 남지 않아서 원인을 지레짐작으로 파악할 수 밖에 없는 상황입니다. </li>
<li>물론 local test시에는 매우 잘 동작합니다.</li>
</ol>
<p>절망하다가 차츰 화가 나기 시작합니다.</p>]]></description></item></channel></rss>